<?xml version="1.0"?>

<robot xmlns="http://drake.mit.edu"
 xmlns:xsi="http://www.w3.org/2001/XMLSchema-instance"
 xsi:schemaLocation="http://drake.mit.edu ../../doc/drakeURDF.xsd" name="catBot">
  <material name="black">
    <color rgba="0.3 0.3 0.3 1" />
  </material>
  <material name="MITred">
    <color rgba=".6 .2 .2 1" />
  </material>
  <material name="blue">
    <color rgba=".2 .2 .6 1" />
  </material>

  <link name="link_A">
    <inertial>
      <origin xyz="-0.050 0 0"/>
      <mass value="1" />
      <inertia ixx=" 0.00045" ixy=" 0.00000" ixz=" 0.00000"iyy=" 0.00106" iyz=" 0.00000" izz=" 0.00106"/>
    </inertial>

    <collision>
      <origin xyz="-0.050 0 0" rpy="0 1.570 0"/>
      <geometry>
        <cylinder length="0.100" radius="0.030"/>
      </geometry>
      <material name="black"/>
    </collision>

    <visual>
      <origin xyz="-0.050 0 0" rpy="0 1.570 0" />
      <geometry>
        <cylinder length="0.100" radius="0.030"/>
      </geometry>
      <material name="black"/>
    </visual>

    <visual>
      <origin xyz="-0.080 0 0.03" rpy="0 1.570 0" />
      <geometry>
        <sphere radius="0.01"/>
      </geometry>
      <material name="MITred"/>
    </visual>
  </link>

  <link name="link_A_aux">
    <inertial>
      <origin xyz="0 0 0"/>
      <mass value="0.0001" />
      <inertia ixx=" 0.00000" ixy=" 0.00000" ixz=" 0.00000"iyy=" 0.00000" iyz=" 0.00000" izz=" 0.00000"/>
    </inertial>
    <visual>
      <origin xyz="0 0 0" rpy="0 0 0"/>
      <geometry>
        <sphere radius="0.01"/>
      </geometry>
      <material name="MITred"/>
    </visual>
    <!-- Middle Joint -->
    <visual>
      <origin xyz="0.03 0 0" rpy="0 0 0"/>
      <geometry>
        <sphere radius="0.01"/>
      </geometry>
      <material name="blue"/>
    </visual>
  </link>
  <joint name="A_revolute" type="revolute">
    <parent link="link_A"/>
    <child link="link_A_aux"/>
    <origin rpy="0 0 0" xyz="0 0 0"/>
    <axis xyz="1 0 0"/>
  <!-- // TODO Limit, controller, dynamcis -->
  </joint>

  <link name="link_B_aux">
    <inertial>
      <origin xyz="0 0 0"/>
      <mass value="0.0001" />
      <inertia ixx=" 0.00000" ixy=" 0.00000" ixz=" 0.00000"iyy=" 0.00000" iyz=" 0.00000" izz=" 0.00000"/>
    </inertial>
    <visual>
      <origin xyz="0.03 0 0" rpy="0 0 0"/>
      <geometry>
        <sphere radius="0.01"/>
      </geometry>
      <material name="MITred"/>
    </visual>
    <!-- Middle Joint -->
    <visual>
      <origin xyz="0 0 0" rpy="0 0 0"/>
      <geometry>
        <sphere radius="0.01"/>
      </geometry>
      <material name="blue"/>
    </visual>
  </link>
  <joint name="middle_revolute" type="revolute">
    <parent link="link_A_aux"/>
    <child link="link_B_aux"/>
    <origin rpy="0 0 0" xyz="0.03 0 0"/>
    <axis xyz="0 1 0"/>
  <!-- // TODO Limit, controller, dynamcis -->
  </joint>


  <link name="link_B">
    <inertial>
      <origin xyz="0.050 0 0"/>
      <mass value="1" />
      <inertia ixx=" 0.00045" ixy=" 0.00000" ixz=" 0.00000"iyy=" 0.00106" iyz=" 0.00000" izz=" 0.00106"/>
    </inertial>

    <collision>
      <origin xyz="0.050 0 0" rpy="0 1.570 0"/>
      <geometry>
        <cylinder length="0.100" radius="0.030"/>
      </geometry>
      <material name="black"/>
    </collision>

    <visual>
      <origin xyz="0.050 0 0" rpy="0 1.570 0" />
      <geometry>
        <cylinder length="0.100" radius="0.030"/>
      </geometry>
      <material name="black"/>
    </visual>

    <visual>
      <origin xyz="0.080 0 0.03" rpy="0 1.570 0" />
      <geometry>
        <sphere radius="0.01"/>
      </geometry>
      <material name="MITred"/>
    </visual>
  </link>
  <joint name="B_revolute" type="revolute">
    <parent link="link_B_aux"/>
    <child link="link_B"/>
    <origin rpy="0 0 0" xyz="0.03 0. 0."/>
    <axis xyz="1 0 0"/>
  <!-- // TODO Limit, controller, dynamcis -->
  </joint>


  <transmission type="SimpleTransmission" name="cat_A_torque">
    <actuator name="torque" />
    <joint name="A_revolute" />
    <mechanicalReduction>1</mechanicalReduction>
  </transmission>
</robot>